Workbook

Sheet OVERVIEW
B1: 🎯 JD-TO-RESUME MATCHING UTILITY
B2: Automated Job Description analysis across 3 professional tracks
B3: AI Transformation • Technical Program Manager • IT Delivery • Product Manager
B5: 🚀 QUICK START — 3 Steps to Get Started
B6: STEP 1 | C6: STEP 2 | D6: STEP 3
B7: 📋 Go to JD_INPUT | C7: 📝 Paste JD into B10 | D7: 🎯 See Best Fit at Row 25
B8: =HYPERLINK("#JD_INPUT!A1","→ Open JD_INPUT sheet") -> → Open JD_INPUT sheet | C8: Ctrl+V works instantly — no manual entry required | D8: Score, keywords, bullets all auto-populate
B10: 🧭 NAVIGATE THE UTILITY — Click any card to jump to that sheet
B11: 📋 | C11: 🤖 | D11: ⚙️
B12: =HYPERLINK("#JD_INPUT!A1","JD_INPUT") -> JD_INPUT | C12: =HYPERLINK("#AI_SCORE!A1","AI_SCORE") -> AI_SCORE | D12: =HYPERLINK("#TPM_SCORE!A1","TPM_SCORE") -> TPM_SCORE
B13: Paste JD • See scores • Get recommendations | C13: AI Transformation Manager scoring engine | D13: Technical Program Manager scoring engine
B15: 🛠️ | C15: 🔑 | D15: 🏆
B16: =HYPERLINK("#ITDM_SCORE!A1","ITDM_SCORE") -> ITDM_SCORE | C16: =HYPERLINK("#KEYWORDS!A1","KEYWORDS") -> KEYWORDS | D16: =HYPERLINK("#FINAL_RECOMMENDATION!A1","FINAL_RECOMMENDATION") -> FINAL_RECOMMENDATION
B17: IT Delivery Manager scoring engine | C17: 45 keyword synonyms • Tier & Track tagged | D17: Final report • Radar chart • Cover letter picker
B19: ✍️ | C19: 💡
B20: =HYPERLINK("#BULLET_GENERATOR!A1","BULLET_GENERATOR") -> BULLET_GENERATOR | C20: PRO TIPS
B21: 45 pre-written resume bullets — copy-ready | C21: Score ≥32 = Strong Match • 25-31 = Good • 18-24 = Moderate • <18 = Skip
B23: 📊 SCORING KEY — Understand the numbers
B24: 🟢 STRONG MATCH | C24: 🔵 GOOD MATCH | D24: 🟡 MODERATE MATCH
B25: Score ≥ 32 | C25: Score 25 – 31 | D25: Score 18 – 24
B26: Apply with confidence | C26: Tailor a few bullets, then apply | D26: Significant tailoring needed
B28: 📎 RESOURCES — Resume & Cover Letter Templates
B29: AI Transformation | C29: Technical Program Mgr | D29: IT Delivery Manager | E29: Product Manager
B30: =HYPERLINK("https://www.genspark.ai/api/files/s/QUBpsO27r","📄 Download Resume") -> 📄 Download Resume | C30: =HYPERLINK("https://www.genspark.ai/api/files/s/BLpvZjmUt","📄 Download Resume") -> 📄 Download Resume | D30: =HYPERLINK("https://www.genspark.ai/api/files/s/kaZPyfr7","📄 Download Resume") -> 📄 Download Resume | E30: Resume - (Template TBD)
B31: =HYPERLINK("https://www.genspark.ai/api/files/s/lkUPzCNe","✉️ Cover Letter") -> ✉️ Cover Letter | C31: =HYPERLINK("https://www.genspark.ai/api/files/s/PxGCoBuk","✉️ Cover Letter") -> ✉️ Cover Letter | D31: =HYPERLINK("https://www.genspark.ai/api/files/s/lPnFfxiB","✉️ Cover Letter") -> ✉️ Cover Letter | E31: Cover Letter - (Template TBD)
E32: PM_SCORE & Bullets 49-63
B33: ⚡ Auto-scoring active — Paste JD in JD_INPUT!B10 and everything updates instantly
B34: Version 2.0 • 8 sheets • 45 keywords • 60 bullet templates • Radar & Bar charts

Sheet JD_INPUT
A1: Job Description Input
A9: PASTE JOB DESCRIPTION HERE
A10: PASTE FULL JD INTO CELL B10 | B10: About The Job The Field Platforms Operations Lead role is a part of the Go-to-Market Capabilities (GTMC), Customer Facing Capabilities (CFC), CRM & Enablers team. The GTMC organization drives best-in-class capabilities and brings value and excellence in commercial operations. The GTMC organization is a key part of the modernization of Sanofi and allows all business operations efforts to be focused on Sanofi "Take the Lead" priorities across products, markets, and pipelines. It accomplishes these goals through realizing the efficiencies of removing silos that exist between our business units, avoiding the duplication and overlapping of resources, standardizing our processes and tools, operating with a One Sanofi approach to accelerate our key capabilities development, and fostering the entrepreneurial spirit by speeding up the decision making process. This role serves as the technical authority for OneCRM US field platform operations, leading the strategic vision for CRM operations, data governance, and platform evolution. This leader designs and implements scalable operational solutions that support multi-brand, multi-market launch requirements, ensuring enterprise-wide CRM performance, data integrity, and continuous platform transformation. This position will work closely with CRM & Enablers Team members in the US, US-based stakeholders, Hyderabad HUB resources, contracted system enhancement resources, Sr. Field Management, the Workday Team, select vendors (i.e. Hibbert), other GTMC pillars, Veeva, and Sanofi Digital to lead the end-to-end design, governance, and evolution of OneCRM US field platform operations. This leader serves as a strategic partner across the OneCRM US ecosystem, influencing platform direction, data governance standards, and operational frameworks that underpin enterprise-wide CRM performance. Main Responsibilities Lead the strategic vision and operational roadmap for OneCRM US field platform operations, ensuring alignment with enterprise CRM standards and business priorities Influence platform strategy and technical architecture decisions across OneCRM US, shaping long-term CRM evolution and downstream system integration Serve as the technical authority for CRM data governance, establishing standards, policies, and frameworks that ensure data integrity across the OneCRM US ecosystem Drive enterprise-wide data governance initiatives, influencing data quality standards across multiple business units and downstream systems Design and implement scalable CRM operational solutions that support multi-brand, multi-market launch requirements across the OneCRM US ecosystem Architect end-to-end operational frameworks and processes that scale with organizational growth and platform evolution Lead and mentor the field platforms operations team, providing technical guidance, knowledge transfer, and career development support Drive capability building across the broader CRM operations community through structured knowledge sharing and best practice development Partner with Platform, Digital, and Business teams to influence technical decisions on incoming platform requests and CRM enhancements Influence senior stakeholder priorities and resource strategies across multiple concurrent launch projects and business units Lead transformation of CRM operational processes, driving adoption of modern approaches and establishing performance measurement frameworks Investigate and remediate escalated inquiries, applying technical expertise to resolve complex issues and prevent recurrence through systemic process improvements Drive cross-functional collaboration across partner GTMC US teams, ensuring operational strategies are integrated with platform and business initiatives About Our Team The CRM & Enablers Team is a part of the GTMC organization in the US. The CRM & Enablers Team strives to support our business customer facing teams by delivering innovative CRM capabilities that are timely, reliable, accurate, and constantly improving. We focus on our customers — both brand teams and customer facing teams — to adapt our CRM platform and operational systems to meet their needs. Our efforts to streamline and maintain OneCRM US bring value and impact to the organization by reducing the manual workload on our customer facing teams, by providing accurate activity data back to reporting systems, and acting as the nexus of data flow to and from Sanofi data systems. This team operates as a strategic partner to the business, driving platform excellence and enabling field force effectiveness at enterprise scale About The Candidate This candidate has a demonstrated track record of leading technical teams, influencing enterprise platform strategy, and designing scalable operational solutions across multiple business units and product launches. They bring deep expertise in CRM operations, data governance, and field platform management, combined with the ability to translate complex technical requirements into enterprise-wide operational frameworks. This leader has experience architecting CRM solutions, driving process transformation, and building organizational capability at scale. They are skilled at influencing senior stakeholders, navigating complex matrix environments, and shaping platform strategy across concurrent launch programs. Strong English communication skills and availability to engage with US stakeholders with significant operational hour overlap are essential. Ideal Experience Bachelor's degree from an accredited four-year college or university (Project Management Masters or MBA preferred) 7+ years of progressive CRM operations and field platform experience with demonstrated leadership 7+ years of experience in Biotechnology or Pharmaceuticals Proven track record of leading technical teams and driving strategic operational initiatives across enterprise-scale programs Experience in solution architecture for CRM platforms and operational frameworks Advanced expertise in data governance, data quality standards, and enterprise data management Advanced skills in managing senior stakeholder relationships across business units and multiple launch projects Experience influencing enterprise-wide platform strategy and operational approaches Strong knowledge and experience with Veeva CRM, Agile processes, and field force management systems A keen eye for improvement opportunities and the demonstrated ability to deliver on these opportunities Clear communication skills with the ability to explain not only the requirements and the "ask", but also the "why" with credibility Motivated, energetic, and a respected contributor who engages and elevates others Ability to change behaviors to evolve to the company's strategies and initiatives Experience working and thriving in a matrix environment Strong English communication skills with the ability to engage and align diverse stakeholders across geographies and functions
B12: =LOWER(B10) -> about the job the field platforms operations lead role is a part of the go-to-market capabilities (gtmc), customer facing capabilities (cfc), crm & enablers team. the gtmc organization drives best-in-class capabilities and brings value and excellence in commercial operations. the gtmc organization is a key part of the modernization of sanofi and allows all business operations efforts to be focused on sanofi "take the lead" priorities across products, markets, and pipelines. it accomplishes these goals through realizing the efficiencies of removing silos that exist between our business units, avoiding the duplication and overlapping of resources, standardizing our processes and tools, operating with a one sanofi approach to accelerate our key capabilities development, and fostering the entrepreneurial spirit by speeding up the decision making process. this role serves as the technical authority for onecrm us field platform operations, leading the strategic vision for crm operations, data governance, and platform evolution. this leader designs and implements scalable operational solutions that support multi-brand, multi-market launch requirements, ensuring enterprise-wide crm performance, data integrity, and continuous platform transformation. this position will work closely with crm & enablers team members in the us, us-based stakeholders, hyderabad hub resources, contracted system enhancement resources, sr. field management, the workday team, select vendors (i.e. hibbert), other gtmc pillars, veeva, and sanofi digital to lead the end-to-end design, governance, and evolution of onecrm us field platform operations. this leader serves as a strategic partner across the onecrm us ecosystem, influencing platform direction, data governance standards, and operational frameworks that underpin enterprise-wide crm performance. main responsibilities lead the strategic vision and operational roadmap for onecrm us field platform operations, ensuring alignment with enterprise crm standards and business priorities influence platform strategy and technical architecture decisions across onecrm us, shaping long-term crm evolution and downstream system integration serve as the technical authority for crm data governance, establishing standards, policies, and frameworks that ensure data integrity across the onecrm us ecosystem drive enterprise-wide data governance initiatives, influencing data quality standards across multiple business units and downstream systems design and implement scalable crm operational solutions that support multi-brand, multi-market launch requirements across the onecrm us ecosystem architect end-to-end operational frameworks and processes that scale with organizational growth and platform evolution lead and mentor the field platforms operations team, providing technical guidance, knowledge transfer, and career development support drive capability building across the broader crm operations community through structured knowledge sharing and best practice development partner with platform, digital, and business teams to influence technical decisions on incoming platform requests and crm enhancements influence senior stakeholder priorities and resource strategies across multiple concurrent launch projects and business units lead transformation of crm operational processes, driving adoption of modern approaches and establishing performance measurement frameworks investigate and remediate escalated inquiries, applying technical expertise to resolve complex issues and prevent recurrence through systemic process improvements drive cross-functional collaboration across partner gtmc us teams, ensuring operational strategies are integrated with platform and business initiatives about our team the crm & enablers team is a part of the gtmc organization in the us. the crm & enablers team strives to support our business customer facing teams by delivering innovative crm capabilities that are timely, reliable, accurate, and constantly improving. we focus on our customers — both brand teams and customer facing teams — to adapt our crm platform and operational systems to meet their needs. our efforts to streamline and maintain onecrm us bring value and impact to the organization by reducing the manual workload on our customer facing teams, by providing accurate activity data back to reporting systems, and acting as the nexus of data flow to and from sanofi data systems. this team operates as a strategic partner to the business, driving platform excellence and enabling field force effectiveness at enterprise scale about the candidate this candidate has a demonstrated track record of leading technical teams, influencing enterprise platform strategy, and designing scalable operational solutions across multiple business units and product launches. they bring deep expertise in crm operations, data governance, and field platform management, combined with the ability to translate complex technical requirements into enterprise-wide operational frameworks. this leader has experience architecting crm solutions, driving process transformation, and building organizational capability at scale. they are skilled at influencing senior stakeholders, navigating complex matrix environments, and shaping platform strategy across concurrent launch programs. strong english communication skills and availability to engage with us stakeholders with significant operational hour overlap are essential. ideal experience bachelor's degree from an accredited four-year college or university (project management masters or mba preferred) 7+ years of progressive crm operations and field platform experience with demonstrated leadership 7+ years of experience in biotechnology or pharmaceuticals proven track record of leading technical teams and driving strategic operational initiatives across enterprise-scale programs experience in solution architecture for crm platforms and operational frameworks advanced expertise in data governance, data quality standards, and enterprise data management advanced skills in managing senior stakeholder relationships across business units and multiple launch projects experience influencing enterprise-wide platform strategy and operational approaches strong knowledge and experience with veeva crm, agile processes, and field force management systems a keen eye for improvement opportunities and the demonstrated ability to deliver on these opportunities clear communication skills with the ability to explain not only the requirements and the "ask", but also the "why" with credibility motivated, energetic, and a respected contributor who engages and elevates others ability to change behaviors to evolve to the company's strategies and initiatives experience working and thriving in a matrix environment strong english communication skills with the ability to engage and align diverse stakeholders across geographies and functions
A14: 🚀 GET FINAL SUGGESTION ➜ (Auto-processes when JD is pasted into B10)
A15: =IF(LEN(B10)<50,"⚠️ Paste a Job Description into cell B10 above (minimum 50 characters). Auto-processing will start immediately.","✅ JD PROCESSED — "&LEN(B10)&" characters analyzed. See Final Recommendation below ↓") -> ✅ JD PROCESSED — 6943 characters analyzed. See Final Recommendation below ↓
A17: 🔍 AUTO-PARSED JD INSIGHTS
A18: 📊 Seniority Level Detected | B18: =IF(LEN(B10)<50,"—",IF(OR(ISNUMBER(SEARCH("chief",B12)),ISNUMBER(SEARCH("cto",B12)),ISNUMBER(SEARCH("cio",B12)),ISNUMBER(SEARCH("cdo",B12))),"C-Suite / Chief",IF(OR(ISNUMBER(SEARCH("svp",B12)),ISNUMBER(SEARCH("evp",B12)),ISNUMBER(SEARCH("senior vice president",B12)),ISNUMBER(SEARCH("executive vice president",B12))),"SVP / EVP",IF(OR(ISNUMBER(SEARCH("vice president",B12)),ISNUMBER(SEARCH(" vp ",B12)),ISNUMBER(SEARCH("vp of",B12))),"VP",IF(OR(ISNUMBER(SEARCH("senior director",B12)),ISNUMBER(SEARCH("sr. director",B12)),ISNUMBER(SEARCH("sr director",B12))),"Senior Director",IF(OR(ISNUMBER(SEARCH("head of",B12)),ISNUMBER(SEARCH("director",B12))),"Director / Head",IF(OR(ISNUMBER(SEARCH("principal",B12)),ISNUMBER(SEARCH("staff ",B12)),ISNUMBER(SEARCH("distinguished",B12))),"Principal / Staff",IF(OR(ISNUMBER(SEARCH("senior manager",B12)),ISNUMBER(SEARCH("sr manager",B12)),ISNUMBER(SEARCH("sr. manager",B12))),"Senior Manager",IF(OR(ISNUMBER(SEARCH("manager",B12)),ISNUMBER(SEARCH("lead ",B12))),"Manager / Lead","Individual Contributor / Not detected"))))))))) -> Manager / Lead
A19: 💰 Salary Range (parsed) | B19: =IF(LEN(B10)<50,"—",IF(ISNUMBER(SEARCH("$",B10)),"Salary mentioned in JD — scan for $ figures",IF(OR(ISNUMBER(SEARCH("compensation",B12)),ISNUMBER(SEARCH("salary",B12)),ISNUMBER(SEARCH("pay range",B12)),ISNUMBER(SEARCH("base pay",B12))),"Compensation referenced (no explicit $ figure)","Not specified in JD"))) -> Not specified in JD
A20: 📍 Work Location / Mode | B20: =IF(LEN(B10)<50,"—",IF(ISNUMBER(SEARCH("remote",B12)),IF(ISNUMBER(SEARCH("hybrid",B12)),"Hybrid (Remote + Onsite)",IF(ISNUMBER(SEARCH("fully remote",B12)),"Fully Remote","Remote friendly")),IF(ISNUMBER(SEARCH("hybrid",B12)),"Hybrid",IF(OR(ISNUMBER(SEARCH("onsite",B12)),ISNUMBER(SEARCH("on-site",B12)),ISNUMBER(SEARCH("in-office",B12)),ISNUMBER(SEARCH("in office",B12))),"Onsite / In-office",IF(B5<>"",B5,"Not specified"))))) -> Not specified
A21: 🕐 Employment Type | B21: =IF(LEN(B10)<50,"—",IF(OR(ISNUMBER(SEARCH("contract",B12)),ISNUMBER(SEARCH("contractor",B12)),ISNUMBER(SEARCH("c2c",B12)),ISNUMBER(SEARCH("w2 contract",B12))),"Contract / C2C",IF(OR(ISNUMBER(SEARCH("part-time",B12)),ISNUMBER(SEARCH("part time",B12))),"Part-Time",IF(OR(ISNUMBER(SEARCH("intern",B12)),ISNUMBER(SEARCH("internship",B12))),"Internship",IF(OR(ISNUMBER(SEARCH("full-time",B12)),ISNUMBER(SEARCH("full time",B12)),ISNUMBER(SEARCH("permanent",B12))),"Full-Time / Permanent","Full-Time (assumed)"))))) -> Contract / C2C
A22: 🏢 Industry Signals | B22: =IF(LEN(B10)<50,"—",TRIM(IF(OR(ISNUMBER(SEARCH("banking",B12)),ISNUMBER(SEARCH("financial services",B12)),ISNUMBER(SEARCH("fintech",B12)),ISNUMBER(SEARCH("insurance",B12))),"Financial Services ","")&IF(OR(ISNUMBER(SEARCH("healthcare",B12)),ISNUMBER(SEARCH("pharma",B12)),ISNUMBER(SEARCH("life sciences",B12))),"Healthcare/Pharma ","")&IF(OR(ISNUMBER(SEARCH("retail",B12)),ISNUMBER(SEARCH("e-commerce",B12)),ISNUMBER(SEARCH("ecommerce",B12))),"Retail/E-commerce ","")&IF(OR(ISNUMBER(SEARCH("manufacturing",B12)),ISNUMBER(SEARCH("industrial",B12))),"Manufacturing ","")&IF(OR(ISNUMBER(SEARCH("consulting",B12)),ISNUMBER(SEARCH("advisory",B12))),"Consulting ","")&IF(OR(ISNUMBER(SEARCH("technology",B12)),ISNUMBER(SEARCH("saas",B12)),ISNUMBER(SEARCH("software",B12))),"Technology/SaaS ",""))) -> Healthcare/Pharma Technology/SaaS
A24: 🏆 FINAL RECOMMENDATION (auto-updates when JD is pasted)
A25: 🎯 BEST-FIT RESUME | B25: =IF(LEN(B10)<50,"⏳ Waiting for JD input...",INDEX({"AI Transformation Manager","Technical Program Manager","IT Delivery Manager","Product Manager"},MATCH(MAX(AI_SCORE!D26,TPM_SCORE!D26,ITDM_SCORE!D26,PM_SCORE!D26),CHOOSE({1;2;3;4},AI_SCORE!D26,TPM_SCORE!D26,ITDM_SCORE!D26,PM_SCORE!D26),0))) -> Technical Program Manager
A26: 📈 Best Score & Match Level | B26: =IF(LEN(B10)<50,"—",MAX(AI_SCORE!D26,TPM_SCORE!D26,ITDM_SCORE!D26,PM_SCORE!D26)&" points → "&IF(MAX(AI_SCORE!D26,TPM_SCORE!D26,ITDM_SCORE!D26,PM_SCORE!D26)>=32,"🟢 STRONG MATCH — Apply with confidence",IF(MAX(AI_SCORE!D26,TPM_SCORE!D26,ITDM_SCORE!D26,PM_SCORE!D26)>=25,"🔵 GOOD MATCH — Tailor a few bullets",IF(MAX(AI_SCORE!D26,TPM_SCORE!D26,ITDM_SCORE!D26,PM_SCORE!D26)>=18,"🟡 MODERATE MATCH — Significant tailoring needed","🔴 WEAK MATCH — Reposition heavily or skip")))) -> 22 points → 🟡 MODERATE MATCH — Significant tailoring needed
A27: 📄 Recommended Cover Letter | B27: =IF(LEN(B10)<50,"—",IF(B25="AI Transformation Manager","Use AI Transformation Manager Cover Letter → https://www.genspark.ai/api/files/s/lkUPzCNe",IF(B25="Technical Program Manager","Use Technical Program Manager Cover Letter → https://www.genspark.ai/api/files/s/PxGCoBuk",IF(B25="IT Delivery Manager","Use IT Delivery Manager Cover Letter → https://www.genspark.ai/api/files/s/lPnFfxiB","Use Product Manager Cover Letter → (Template TBD)")))) -> Use Technical Program Manager Cover Letter → https://www.genspark.ai/api/files/s/PxGCoBuk
A28: 🎬 Top Action Before Applying | B28: =IF(LEN(B10)<50,"—","1) Mirror top JD keywords in Professional Summary 2) Move "&B25&" experience to top 3) Add 1 quantified bullet per top-scoring keyword 4) Re-title header to match JD role 5) Reference JD industry in summary") -> 1) Mirror top JD keywords in Professional Summary 2) Move Technical Program Manager experience to top 3) Add 1 quantified bullet per top-scoring keyword 4) Re-title header to match JD role 5) Reference JD industry in summary
A30: 📊 TRACK-BY-TRACK SCORE BREAKDOWN
A31: Track | B31: Score | Match Level | Progress Bar (20 chars)
A32: 🤖 AI Transformation Manager | B32: =IF(LEN(B10)<50,"—",AI_SCORE!D26&" pts | "&IF(AI_SCORE!D26>=32,"🟢 STRONG",IF(AI_SCORE!D26>=25,"🔵 GOOD",IF(AI_SCORE!D26>=18,"🟡 MODERATE","🔴 WEAK")))&" | "&REPT("█",MIN(20,AI_SCORE!D26/2))&REPT("░",MAX(0,20-MIN(20,AI_SCORE!D26/2)))) -> 17 pts | 🔴 WEAK | ████████░░░░░░░░░░░
A33: ⚙️ Technical Program Manager | B33: =IF(LEN(B10)<50,"—",TPM_SCORE!D26&" pts | "&IF(TPM_SCORE!D26>=32,"🟢 STRONG",IF(TPM_SCORE!D26>=25,"🔵 GOOD",IF(TPM_SCORE!D26>=18,"🟡 MODERATE","🔴 WEAK")))&" | "&REPT("█",MIN(20,TPM_SCORE!D26/2))&REPT("░",MAX(0,20-MIN(20,TPM_SCORE!D26/2)))) -> 22 pts | 🟡 MODERATE | ███████████░░░░░░░░░
A34: 🛠️ IT Delivery Manager | B34: =IF(LEN(B10)<50,"—",ITDM_SCORE!D26&" pts | "&IF(ITDM_SCORE!D26>=32,"🟢 STRONG",IF(ITDM_SCORE!D26>=25,"🔵 GOOD",IF(ITDM_SCORE!D26>=18,"🟡 MODERATE","🔴 WEAK")))&" | "&REPT("█",MIN(20,ITDM_SCORE!D26/2))&REPT("░",MAX(0,20-MIN(20,ITDM_SCORE!D26/2)))) -> 9 pts | 🔴 WEAK | ████░░░░░░░░░░░░░░░
A35: 📦 Product Manager | B35: =IF(LEN(B10)<50,"—",PM_SCORE!D26&" pts | "&IF(PM_SCORE!D26>=32,"🟢 STRONG",IF(PM_SCORE!D26>=25,"🔵 GOOD",IF(PM_SCORE!D26>=18,"🟡 MODERATE","🔴 WEAK")))&" | "&REPT("█",MIN(20,PM_SCORE!D26/2))&REPT("░",MAX(0,20-MIN(20,PM_SCORE!D26/2)))) -> 16 pts | 🔴 WEAK | ████████░░░░░░░░░░░░
A36: 🎯 GAP ANALYSIS — Score Delta vs. Best Fit
A37: AI vs Best | B37: =IF(LEN(B10)<50,"—",(AI_SCORE!D26-MAX(AI_SCORE!D26,TPM_SCORE!D26,ITDM_SCORE!D26))&" pts ("&IF(AI_SCORE!D26=MAX(AI_SCORE!D26,TPM_SCORE!D26,ITDM_SCORE!D26),"🏆 BEST FIT","behind best fit")&")") -> -5 pts (behind best fit)
A38: TPM vs Best | B38: =IF(LEN(B10)<50,"—",(TPM_SCORE!D26-MAX(AI_SCORE!D26,TPM_SCORE!D26,ITDM_SCORE!D26))&" pts ("&IF(TPM_SCORE!D26=MAX(AI_SCORE!D26,TPM_SCORE!D26,ITDM_SCORE!D26),"🏆 BEST FIT","behind best fit")&")") -> 0 pts (🏆 BEST FIT)
A39: ITDM vs Best | B39: =IF(LEN(B10)<50,"—",(ITDM_SCORE!D26-MAX(AI_SCORE!D26,TPM_SCORE!D26,ITDM_SCORE!D26))&" pts ("&IF(ITDM_SCORE!D26=MAX(AI_SCORE!D26,TPM_SCORE!D26,ITDM_SCORE!D26),"🏆 BEST FIT","behind best fit")&")") -> -13 pts (behind best fit)
A40: PM vs Best | B40: =IF(LEN(B10)<50,"—",(PM_SCORE!D26-MAX(AI_SCORE!D26,TPM_SCORE!D26,ITDM_SCORE!D26,PM_SCORE!D26))&" pts ("&IF(PM_SCORE!D26=MAX(AI_SCORE!D26,TPM_SCORE!D26,ITDM_SCORE!D26,PM_SCORE!D26),"🏆 BEST FIT","behind best fit")&")") -> -6 pts (behind best fit)
A41: ℹ️ How it works | B41: Paste JD into B10 → All 3 track scores update instantly → Best-fit resume appears at row 25 → Radar chart on FINAL_RECOMMENDATION visualizes 3-track comparison. No manual entry required.
A43: TOP MISSING KEYWORDS - Best Fit
A44: For Best-Fit Track | B44: =IF(LEN(B10)<50,"Paste JD first","Top 5 for: "&B25) -> Top 5 for: Technical Program Manager
A45: ① Missing #1 | B45: =IF(LEN(B10)<50,"—",IF(B25="AI Transformation Manager",AI_SCORE!B32,IF(B25="Technical Program Manager",TPM_SCORE!B32,IF(B25="IT Delivery Manager",ITDM_SCORE!B32,PM_SCORE!B32)))) -> Technical program management
A46: ② Missing #2 | B46: =IF(LEN(B10)<50,"—",IF(B25="AI Transformation Manager",AI_SCORE!B33,IF(B25="Technical Program Manager",TPM_SCORE!B33,IF(B25="IT Delivery Manager",ITDM_SCORE!B33,PM_SCORE!B33)))) -> Program delivery
A47: ③ Missing #3 | B47: =IF(LEN(B10)<50,"—",IF(B25="AI Transformation Manager",AI_SCORE!B34,IF(B25="Technical Program Manager",TPM_SCORE!B34,IF(B25="IT Delivery Manager",ITDM_SCORE!B34,PM_SCORE!B34)))) -> Risk management
A48: ④ Missing #4 | B48: =IF(LEN(B10)<50,"—",IF(B25="AI Transformation Manager",AI_SCORE!B35,IF(B25="Technical Program Manager",TPM_SCORE!B35,IF(B25="IT Delivery Manager",ITDM_SCORE!B35,PM_SCORE!B35)))) -> Change management
A49: ⑤ Missing #5 | B49: =IF(LEN(B10)<50,"—",IF(B25="AI Transformation Manager",AI_SCORE!B36,IF(B25="Technical Program Manager",TPM_SCORE!B36,IF(B25="IT Delivery Manager",ITDM_SCORE!B36,PM_SCORE!B36)))) -> Release management
A50: 💡 Score Boost | B50: =IF(LEN(B10)<50,"—","+20 pts potential (boosts "&B25&" to "&(MAX(AI_SCORE!D26,TPM_SCORE!D26,ITDM_SCORE!D26,PM_SCORE!D26)+20)&" pts)") -> +20 pts potential (boosts Technical Program Manager to 42 pts)
A52: ✍️ Resume Bullets | B52: =IF(LEN(B10)<50,"⏳ Paste JD to see bullet suggestions","See BULLET_GENERATOR sheet → "&COUNTIF(BULLET_GENERATOR!E4:E63,"🟢 USE THIS")&" bullets recommended for your JD") -> See BULLET_GENERATOR sheet → 20 bullets recommended for your JD
A54: ⚠️ JD QUALITY & ATS WARNINGS — Data-quality checks before you trust the score
A55: 📏 JD Word Count | B55: =IF(LEN(B10)<50,"⏳ Waiting for JD input",IF(LEN(B10)-LEN(SUBSTITUTE(B10," ",""))+1<150,"🔴 TOO SHORT ("&(LEN(B10)-LEN(SUBSTITUTE(B10," ",""))+1)&" words) — Score may be unreliable. Add more JD content.",IF(LEN(B10)-LEN(SUBSTITUTE(B10," ",""))+1<300,"🟡 SHORT ("&(LEN(B10)-LEN(SUBSTITUTE(B10," ",""))+1)&" words) — Adequate but keyword coverage may be limited",IF(LEN(B10)-LEN(SUBSTITUTE(B10," ",""))+1<800,"🟢 GOOD ("&(LEN(B10)-LEN(SUBSTITUTE(B10," ",""))+1)&" words) — Ideal length for reliable scoring","🔵 LONG ("&(LEN(B10)-LEN(SUBSTITUTE(B10," ",""))+1)&" words) — Comprehensive JD, scores are highly reliable")))) -> 🔵 LONG (892 words) — Comprehensive JD, scores are highly reliable
...

Sheet AI_SCORE
A1: AI Transformation Manager - Scoring
A3: Keyword / Theme | B3: Weight | C3: Auto Score (0,1,2) | D3: Weighted Score | E3: Notes | H3: Contribution
A4: AI transformation | B4: 2 | C4: =IF(LEN(JD_INPUT!$B$12)<5,0,MIN(2,SUMPRODUCT(--ISNUMBER(SEARCH(TRIM(MID(SUBSTITUTE(KEYWORDS!$B$3,"|",REPT(" ",200)),(ROW(INDIRECT("1:"&KEYWORDS!$C$3))-1)*200+1,200)),JD_INPUT!$B$12))))) -> 0 | D4: =B4*C4 -> 0 | E4: =IF(C4=0,"No keyword match",IF(C4=1,"1 variant matched","2+ variants matched")) -> No keyword match | G4: =IF(C4=0,COUNTIF($C$4:C4,0),"") -> 1 | H4: =IF(D4=0,REPT("░",20),REPT("█",MIN(20,D4*5))&REPT("░",MAX(0,20-MIN(20,D4*5)))) -> ░░░░░░░░░░░░░░░░░░░░
A5: Digital transformation | B5: 2 | C5: =IF(LEN(JD_INPUT!$B$12)<5,0,MIN(2,SUMPRODUCT(--ISNUMBER(SEARCH(TRIM(MID(SUBSTITUTE(KEYWORDS!$B$4,"|",REPT(" ",200)),(ROW(INDIRECT("1:"&KEYWORDS!$C$4))-1)*200+1,200)),JD_INPUT!$B$12))))) -> 0 | D5: =B5*C5 -> 0 | E5: =IF(C5=0,"No keyword match",IF(C5=1,"1 variant matched","2+ variants matched")) -> No keyword match | G5: =IF(C5=0,COUNTIF($C$4:C5,0),"") -> 2 | H5: =IF(D5=0,REPT("░",20),REPT("█",MIN(20,D5*5))&REPT("░",MAX(0,20-MIN(20,D5*5)))) -> ░░░░░░░░░░░░░░░░░░░░
A6: Generative AI / GenAI | B6: 2 | C6: =IF(LEN(JD_INPUT!$B$12)<5,0,MIN(2,SUMPRODUCT(--ISNUMBER(SEARCH(TRIM(MID(SUBSTITUTE(KEYWORDS!$B$5,"|",REPT(" ",200)),(ROW(INDIRECT("1:"&KEYWORDS!$C$5))-1)*200+1,200)),JD_INPUT!$B$12))))) -> 0 | D6: =B6*C6 -> 0 | E6: =IF(C6=0,"No keyword match",IF(C6=1,"1 variant matched","2+ variants matched")) -> No keyword match | G6: =IF(C6=0,COUNTIF($C$4:C6,0),"") -> 3 | H6: =IF(D6=0,REPT("░",20),REPT("█",MIN(20,D6*5))&REPT("░",MAX(0,20-MIN(20,D6*5)))) -> ░░░░░░░░░░░░░░░░░░░░
A7: Intelligent automation | B7: 2 | C7: =IF(LEN(JD_INPUT!$B$12)<5,0,MIN(2,SUMPRODUCT(--ISNUMBER(SEARCH(TRIM(MID(SUBSTITUTE(KEYWORDS!$B$6,"|",REPT(" ",200)),(ROW(INDIRECT("1:"&KEYWORDS!$C$6))-1)*200+1,200)),JD_INPUT!$B$12))))) -> 0 | D7: =B7*C7 -> 0 | E7: =IF(C7=0,"No keyword match",IF(C7=1,"1 variant matched","2+ variants matched")) -> No keyword match | G7: =IF(C7=0,COUNTIF($C$4:C7,0),"") -> 4 | H7: =IF(D7=0,REPT("░",20),REPT("█",MIN(20,D7*5))&REPT("░",MAX(0,20-MIN(20,D7*5)))) -> ░░░░░░░░░░░░░░░░░░░░
A8: AI adoption / AI strategy | B8: 2 | C8: =IF(LEN(JD_INPUT!$B$12)<5,0,MIN(2,SUMPRODUCT(--ISNUMBER(SEARCH(TRIM(MID(SUBSTITUTE(KEYWORDS!$B$7,"|",REPT(" ",200)),(ROW(INDIRECT("1:"&KEYWORDS!$C$7))-1)*200+1,200)),JD_INPUT!$B$12))))) -> 0 | D8: =B8*C8 -> 0 | E8: =IF(C8=0,"No keyword match",IF(C8=1,"1 variant matched","2+ variants matched")) -> No keyword match | G8: =IF(C8=0,COUNTIF($C$4:C8,0),"") -> 5 | H8: =IF(D8=0,REPT("░",20),REPT("█",MIN(20,D8*5))&REPT("░",MAX(0,20-MIN(20,D8*5)))) -> ░░░░░░░░░░░░░░░░░░░░
A9: Transformation roadmap | B9: 2 | C9: =IF(LEN(JD_INPUT!$B$12)<5,0,MIN(2,SUMPRODUCT(--ISNUMBER(SEARCH(TRIM(MID(SUBSTITUTE(KEYWORDS!$B$8,"|",REPT(" ",200)),(ROW(INDIRECT("1:"&KEYWORDS!$C$8))-1)*200+1,200)),JD_INPUT!$B$12))))) -> 0 | D9: =B9*C9 -> 0 | E9: =IF(C9=0,"No keyword match",IF(C9=1,"1 variant matched","2+ variants matched")) -> No keyword match | G9: =IF(C9=0,COUNTIF($C$4:C9,0),"") -> 6 | H9: =IF(D9=0,REPT("░",20),REPT("█",MIN(20,D9*5))&REPT("░",MAX(0,20-MIN(20,D9*5)))) -> ░░░░░░░░░░░░░░░░░░░░
A10: Enterprise modernization | B10: 2 | C10: =IF(LEN(JD_INPUT!$B$12)<5,0,MIN(2,SUMPRODUCT(--ISNUMBER(SEARCH(TRIM(MID(SUBSTITUTE(KEYWORDS!$B$9,"|",REPT(" ",200)),(ROW(INDIRECT("1:"&KEYWORDS!$C$9))-1)*200+1,200)),JD_INPUT!$B$12))))) -> 0 | D10: =B10*C10 -> 0 | E10: =IF(C10=0,"No keyword match",IF(C10=1,"1 variant matched","2+ variants matched")) -> No keyword match | G10: =IF(C10=0,COUNTIF($C$4:C10,0),"") -> 7 | H10: =IF(D10=0,REPT("░",20),REPT("█",MIN(20,D10*5))&REPT("░",MAX(0,20-MIN(20,D10*5)))) -> ░░░░░░░░░░░░░░░░░░░░
A11: Change management | B11: 2 | C11: =IF(LEN(JD_INPUT!$B$12)<5,0,MIN(2,SUMPRODUCT(--ISNUMBER(SEARCH(TRIM(MID(SUBSTITUTE(KEYWORDS!$B$10,"|",REPT(" ",200)),(ROW(INDIRECT("1:"&KEYWORDS!$C$10))-1)*200+1,200)),JD_INPUT!$B$12))))) -> 1 | D11: =B11*C11 -> 2 | E11: =IF(C11=0,"No keyword match",IF(C11=1,"1 variant matched","2+ variants matched")) -> 1 variant matched | G11: =IF(C11=0,COUNTIF($C$4:C11,0),"") | H11: =IF(D11=0,REPT("░",20),REPT("█",MIN(20,D11*5))&REPT("░",MAX(0,20-MIN(20,D11*5)))) -> ██████████░░░░░░░░░░
A12: Stakeholder governance | B12: 2 | C12: =IF(LEN(JD_INPUT!$B$12)<5,0,MIN(2,SUMPRODUCT(--ISNUMBER(SEARCH(TRIM(MID(SUBSTITUTE(KEYWORDS!$B$11,"|",REPT(" ",200)),(ROW(INDIRECT("1:"&KEYWORDS!$C$11))-1)*200+1,200)),JD_INPUT!$B$12))))) -> 2 | D12: =B12*C12 -> 4 | E12: =IF(C12=0,"No keyword match",IF(C12=1,"1 variant matched","2+ variants matched")) -> 2+ variants matched | G12: =IF(C12=0,COUNTIF($C$4:C12,0),"") | H12: =IF(D12=0,REPT("░",20),REPT("█",MIN(20,D12*5))&REPT("░",MAX(0,20-MIN(20,D12*5)))) -> ████████████████████
A13: CRM transformation | B13: 2 | C13: =IF(LEN(JD_INPUT!$B$12)<5,0,MIN(2,SUMPRODUCT(--ISNUMBER(SEARCH(TRIM(MID(SUBSTITUTE(KEYWORDS!$B$12,"|",REPT(" ",200)),(ROW(INDIRECT("1:"&KEYWORDS!$C$12))-1)*200+1,200)),JD_INPUT!$B$12))))) -> 0 | D13: =B13*C13 -> 0 | E13: =IF(C13=0,"No keyword match",IF(C13=1,"1 variant matched","2+ variants matched")) -> No keyword match | G13: =IF(C13=0,COUNTIF($C$4:C13,0),"") -> 8 | H13: =IF(D13=0,REPT("░",20),REPT("█",MIN(20,D13*5))&REPT("░",MAX(0,20-MIN(20,D13*5)))) -> ░░░░░░░░░░░░░░░░░░░░
A14: Salesforce / Siebel / ServiceNow | B14: 2 | C14: =IF(LEN(JD_INPUT!$B$12)<5,0,MIN(2,SUMPRODUCT(--ISNUMBER(SEARCH(TRIM(MID(SUBSTITUTE(KEYWORDS!$B$13,"|",REPT(" ",200)),(ROW(INDIRECT("1:"&KEYWORDS!$C$13))-1)*200+1,200)),JD_INPUT!$B$12))))) -> 0 | D14: =B14*C14 -> 0 | E14: =IF(C14=0,"No keyword match",IF(C14=1,"1 variant matched","2+ variants matched")) -> No keyword match | G14: =IF(C14=0,COUNTIF($C$4:C14,0),"") -> 9 | H14: =IF(D14=0,REPT("░",20),REPT("█",MIN(20,D14*5))&REPT("░",MAX(0,20-MIN(20,D14*5)))) -> ░░░░░░░░░░░░░░░░░░░░
A15: Cloud migration | B15: 2 | C15: =IF(LEN(JD_INPUT!$B$12)<5,0,MIN(2,SUMPRODUCT(--ISNUMBER(SEARCH(TRIM(MID(SUBSTITUTE(KEYWORDS!$B$14,"|",REPT(" ",200)),(ROW(INDIRECT("1:"&KEYWORDS!$C$14))-1)*200+1,200)),JD_INPUT!$B$12))))) -> 0 | D15: =B15*C15 -> 0 | E15: =IF(C15=0,"No keyword match",IF(C15=1,"1 variant matched","2+ variants matched")) -> No keyword match | G15: =IF(C15=0,COUNTIF($C$4:C15,0),"") -> 10 | H15: =IF(D15=0,REPT("░",20),REPT("█",MIN(20,D15*5))&REPT("░",MAX(0,20-MIN(20,D15*5)))) -> ░░░░░░░░░░░░░░░░░░░░
A16: Process optimization | B16: 2 | C16: =IF(LEN(JD_INPUT!$B$12)<5,0,MIN(2,SUMPRODUCT(--ISNUMBER(SEARCH(TRIM(MID(SUBSTITUTE(KEYWORDS!$B$15,"|",REPT(" ",200)),(ROW(INDIRECT("1:"&KEYWORDS!$C$15))-1)*200+1,200)),JD_INPUT!$B$12))))) -> 1 | D16: =B16*C16 -> 2 | E16: =IF(C16=0,"No keyword match",IF(C16=1,"1 variant matched","2+ variants matched")) -> 1 variant matched | G16: =IF(C16=0,COUNTIF($C$4:C16,0),"") | H16: =IF(D16=0,REPT("░",20),REPT("█",MIN(20,D16*5))&REPT("░",MAX(0,20-MIN(20,D16*5)))) -> ██████████░░░░░░░░░░
A17: Operating model transformation | B17: 2 | C17: =IF(LEN(JD_INPUT!$B$12)<5,0,MIN(2,SUMPRODUCT(--ISNUMBER(SEARCH(TRIM(MID(SUBSTITUTE(KEYWORDS!$B$16,"|",REPT(" ",200)),(ROW(INDIRECT("1:"&KEYWORDS!$C$16))-1)*200+1,200)),JD_INPUT!$B$12))))) -> 1 | D17: =B17*C17 -> 2 | E17: =IF(C17=0,"No keyword match",IF(C17=1,"1 variant matched","2+ variants matched")) -> 1 variant matched | G17: =IF(C17=0,COUNTIF($C$4:C17,0),"") | H17: =IF(D17=0,REPT("░",20),REPT("█",MIN(20,D17*5))&REPT("░",MAX(0,20-MIN(20,D17*5)))) -> ██████████░░░░░░░░░░
A18: Cross-functional leadership | B18: 2 | C18: =IF(LEN(JD_INPUT!$B$12)<5,0,MIN(2,SUMPRODUCT(--ISNUMBER(SEARCH(TRIM(MID(SUBSTITUTE(KEYWORDS!$B$17,"|",REPT(" ",200)),(ROW(INDIRECT("1:"&KEYWORDS!$C$17))-1)*200+1,200)),JD_INPUT!$B$12))))) -> 1 | D18: =B18*C18 -> 2 | E18: =IF(C18=0,"No keyword match",IF(C18=1,"1 variant matched","2+ variants matched")) -> 1 variant matched | G18: =IF(C18=0,COUNTIF($C$4:C18,0),"") | H18: =IF(D18=0,REPT("░",20),REPT("█",MIN(20,D18*5))&REPT("░",MAX(0,20-MIN(20,D18*5)))) -> ██████████░░░░░░░░░░
A19: TOTAL KEYWORD SCORE | D19: =SUM(D4:D18) -> 12 | H19: =IF(D19=0,"⏳ Waiting for JD",REPT("█",MIN(30,D19))&" ("&D19&"/30)") -> ████████████ (12/30)
H20: █████ Strong (4) ██░░░ Partial (2) ░░░░░ Missing (0)
A21: Additional Scoring Factors (Rate 0-5)
A22: Responsibility Pattern Match (0-5) | D22: =MIN(5,IF(ISNUMBER(SEARCH("ai transformation",JD_INPUT!$B$12)),1,0)+IF(ISNUMBER(SEARCH("digital transformation",JD_INPUT!$B$12)),1,0)+IF(ISNUMBER(SEARCH("automation",JD_INPUT!$B$12)),1,0)+IF(ISNUMBER(SEARCH("modernization",JD_INPUT!$B$12)),1,0)+IF(ISNUMBER(SEARCH("innovation",JD_INPUT!$B$12)),1,0)) -> 1 | E22: How well does the JD's responsibilities align with AI Transformation role pattern?
A23: Company Match (0-5) | D23: =MIN(5,IF(ISNUMBER(SEARCH("ai",JD_INPUT!$B$12)),1,0)+IF(ISNUMBER(SEARCH("transformation",JD_INPUT!$B$12)),1,0)+IF(ISNUMBER(SEARCH("digital",JD_INPUT!$B$12)),1,0)+IF(ISNUMBER(SEARCH("consulting",JD_INPUT!$B$12)),1,0)+IF(ISNUMBER(SEARCH("strategy",JD_INPUT!$B$12)),1,0)) -> 4 | E23: Is the company AI-focused, transformation-led, or consulting-style?
A24: Red Flag Penalty (0-5) | D24: =MIN(5,IF(ISNUMBER(SEARCH("python",JD_INPUT!$B$12)),1,0)+IF(ISNUMBER(SEARCH("tensorflow",JD_INPUT!$B$12)),1,0)+IF(ISNUMBER(SEARCH("pytorch",JD_INPUT!$B$12)),1,0)+IF(ISNUMBER(SEARCH("data scientist",JD_INPUT!$B$12)),1,0)+IF(ISNUMBER(SEARCH("ml engineer",JD_INPUT!$B$12)),1,0)) -> 0 | E24: Penalty if JD requires deep hands-on ML/data science engineering
A26: FINAL SCORE | D26: =D19+D22+D23-D24 -> 17
A28: Key Gaps / Suggested Edits
A30: TOP MISSING KEYWORDS
A31: Rank | B31: Missing Keyword | C31: Weight | D31: Boost | E31: Action
A32: 1 | B32: =IFERROR(INDEX($A$4:$A$18,MATCH(1,$G$4:$G$18,0)),"All matched") -> AI transformation | C32: =IFERROR(VLOOKUP(B32,$A$4:$B$18,2,FALSE),"-") -> 2 | D32: =IF(ISNUMBER(C32),"+"&(C32*2)&" pts","-") -> +4 pts | E32: ="Add a bullet mentioning: "&B32 -> Add a bullet mentioning: AI transformation
A33: 2 | B33: =IFERROR(INDEX($A$4:$A$18,MATCH(2,$G$4:$G$18,0)),"All matched") -> Digital transformation | C33: =IFERROR(VLOOKUP(B33,$A$4:$B$18,2,FALSE),"-") -> 2 | D33: =IF(ISNUMBER(C33),"+"&(C33*2)&" pts","-") -> +4 pts | E33: ="Add a bullet mentioning: "&B33 -> Add a bullet mentioning: Digital transformation
A34: 3 | B34: =IFERROR(INDEX($A$4:$A$18,MATCH(3,$G$4:$G$18,0)),"All matched") -> Generative AI / GenAI | C34: =IFERROR(VLOOKUP(B34,$A$4:$B$18,2,FALSE),"-") -> 2 | D34: =IF(ISNUMBER(C34),"+"&(C34*2)&" pts","-") -> +4 pts | E34: ="Add a bullet mentioning: "&B34 -> Add a bullet mentioning: Generative AI / GenAI
A35: 4 | B35: =IFERROR(INDEX($A$4:$A$18,MATCH(4,$G$4:$G$18,0)),"All matched") -> Intelligent automation | C35: =IFERROR(VLOOKUP(B35,$A$4:$B$18,2,FALSE),"-") -> 2 | D35: =IF(ISNUMBER(C35),"+"&(C35*2)&" pts","-") -> +4 pts | E35: ="Add a bullet mentioning: "&B35 -> Add a bullet mentioning: Intelligent automation
A36: 5 | B36: =IFERROR(INDEX($A$4:$A$18,MATCH(5,$G$4:$G$18,0)),"All matched") -> AI adoption / AI strategy | C36: =IFERROR(VLOOKUP(B36,$A$4:$B$18,2,FALSE),"-") -> 2 | D36: =IF(ISNUMBER(C36),"+"&(C36*2)&" pts","-") -> +4 pts | E36: ="Add a bullet mentioning: "&B36 -> Add a bullet mentioning: AI adoption / AI strategy

Sheet TPM_SCORE
A1: Technical Program Manager - Scoring
A3: Keyword / Theme | B3: Weight | C3: Auto Score (0,1,2) | D3: Weighted Score | E3: Notes | H3: Contribution
A4: Technical program management | B4: 2 | C4: =IF(LEN(JD_INPUT!$B$12)<5,0,MIN(2,SUMPRODUCT(--ISNUMBER(SEARCH(TRIM(MID(SUBSTITUTE(KEYWORDS!$B$18,"|",REPT(" ",200)),(ROW(INDIRECT("1:"&KEYWORDS!$C$18))-1)*200+1,200)),JD_INPUT!$B$12))))) -> 0 | D4: =B4*C4 -> 0 | E4: =IF(C4=0,"No keyword match",IF(C4=1,"1 variant matched","2+ variants matched")) -> No keyword match | G4: =IF(C4=0,COUNTIF($C$4:C4,0),"") -> 1 | H4: =IF(D4=0,REPT("░",20),REPT("█",MIN(20,D4*5))&REPT("░",MAX(0,20-MIN(20,D4*5)))) -> ░░░░░░░░░░░░░░░░░░░░
A5: Program delivery | B5: 2 | C5: =IF(LEN(JD_INPUT!$B$12)<5,0,MIN(2,SUMPRODUCT(--ISNUMBER(SEARCH(TRIM(MID(SUBSTITUTE(KEYWORDS!$B$19,"|",REPT(" ",200)),(ROW(INDIRECT("1:"&KEYWORDS!$C$19))-1)*200+1,200)),JD_INPUT!$B$12))))) -> 0 | D5: =B5*C5 -> 0 | E5: =IF(C5=0,"No keyword match",IF(C5=1,"1 variant matched","2+ variants matched")) -> No keyword match | G5: =IF(C5=0,COUNTIF($C$4:C5,0),"") -> 2 | H5: =IF(D5=0,REPT("░",20),REPT("█",MIN(20,D5*5))&REPT("░",MAX(0,20-MIN(20,D5*5)))) -> ░░░░░░░░░░░░░░░░░░░░
A6: Roadmap execution | B6: 2 | C6: =IF(LEN(JD_INPUT!$B$12)<5,0,MIN(2,SUMPRODUCT(--ISNUMBER(SEARCH(TRIM(MID(SUBSTITUTE(KEYWORDS!$B$20,"|",REPT(" ",200)),(ROW(INDIRECT("1:"&KEYWORDS!$C$20))-1)*200+1,200)),JD_INPUT!$B$12))))) -> 1 | D6: =B6*C6 -> 2 | E6: =IF(C6=0,"No keyword match",IF(C6=1,"1 variant matched","2+ variants matched")) -> 1 variant matched | G6: =IF(C6=0,COUNTIF($C$4:C6,0),"") | H6: =IF(D6=0,REPT("░",20),REPT("█",MIN(20,D6*5))&REPT("░",MAX(0,20-MIN(20,D6*5)))) -> ██████████░░░░░░░░░░
A7: Cross-functional leadership | B7: 2 | C7: =IF(LEN(JD_INPUT!$B$12)<5,0,MIN(2,SUMPRODUCT(--ISNUMBER(SEARCH(TRIM(MID(SUBSTITUTE(KEYWORDS!$B$21,"|",REPT(" ",200)),(ROW(INDIRECT("1:"&KEYWORDS!$C$21))-1)*200+1,200)),JD_INPUT!$B$12))))) -> 1 | D7: =B7*C7 -> 2 | E7: =IF(C7=0,"No keyword match",IF(C7=1,"1 variant matched","2+ variants matched")) -> 1 variant matched | G7: =IF(C7=0,COUNTIF($C$4:C7,0),"") | H7: =IF(D7=0,REPT("░",20),REPT("█",MIN(20,D7*5))&REPT("░",MAX(0,20-MIN(20,D7*5)))) -> ██████████░░░░░░░░░░
A8: Stakeholder management | B8: 2 | C8: =IF(LEN(JD_INPUT!$B$12)<5,0,MIN(2,SUMPRODUCT(--ISNUMBER(SEARCH(TRIM(MID(SUBSTITUTE(KEYWORDS!$B$22,"|",REPT(" ",200)),(ROW(INDIRECT("1:"&KEYWORDS!$C$22))-1)*200+1,200)),JD_INPUT!$B$12))))) -> 1 | D8: =B8*C8 -> 2 | E8: =IF(C8=0,"No keyword match",IF(C8=1,"1 variant matched","2+ variants matched")) -> 1 variant matched | G8: =IF(C8=0,COUNTIF($C$4:C8,0),"") | H8: =IF(D8=0,REPT("░",20),REPT("█",MIN(20,D8*5))&REPT("░",MAX(0,20-MIN(20,D8*5)))) -> ██████████░░░░░░░░░░
A9: Risk management | B9: 2 | C9: =IF(LEN(JD_INPUT!$B$12)<5,0,MIN(2,SUMPRODUCT(--ISNUMBER(SEARCH(TRIM(MID(SUBSTITUTE(KEYWORDS!$B$23,"|",REPT(" ",200)),(ROW(INDIRECT("1:"&KEYWORDS!$C$23))-1)*200+1,200)),JD_INPUT!$B$12))))) -> 0 | D9: =B9*C9 -> 0 | E9: =IF(C9=0,"No keyword match",IF(C9=1,"1 variant matched","2+ variants matched")) -> No keyword match | G9: =IF(C9=0,COUNTIF($C$4:C9,0),"") -> 3 | H9: =IF(D9=0,REPT("░",20),REPT("█",MIN(20,D9*5))&REPT("░",MAX(0,20-MIN(20,D9*5)))) -> ░░░░░░░░░░░░░░░░░░░░
A10: Dependency management | B10: 2 | C10: =IF(LEN(JD_INPUT!$B$12)<5,0,MIN(2,SUMPRODUCT(--ISNUMBER(SEARCH(TRIM(MID(SUBSTITUTE(KEYWORDS!$B$24,"|",REPT(" ",200)),(ROW(INDIRECT("1:"&KEYWORDS!$C$24))-1)*200+1,200)),JD_INPUT!$B$12))))) -> 1 | D10: =B10*C10 -> 2 | E10: =IF(C10=0,"No keyword match",IF(C10=1,"1 variant matched","2+ variants matched")) -> 1 variant matched | G10: =IF(C10=0,COUNTIF($C$4:C10,0),"") | H10: =IF(D10=0,REPT("░",20),REPT("█",MIN(20,D10*5))&REPT("░",MAX(0,20-MIN(20,D10*5)))) -> ██████████░░░░░░░░░░
A11: Change management | B11: 2 | C11: =IF(LEN(JD_INPUT!$B$12)<5,0,MIN(2,SUMPRODUCT(--ISNUMBER(SEARCH(TRIM(MID(SUBSTITUTE(KEYWORDS!$B$25,"|",REPT(" ",200)),(ROW(INDIRECT("1:"&KEYWORDS!$C$25))-1)*200+1,200)),JD_INPUT!$B$12))))) -> 0 | D11: =B11*C11 -> 0 | E11: =IF(C11=0,"No keyword match",IF(C11=1,"1 variant matched","2+ variants matched")) -> No keyword match | G11: =IF(C11=0,COUNTIF($C$4:C11,0),"") -> 4 | H11: =IF(D11=0,REPT("░",20),REPT("█",MIN(20,D11*5))&REPT("░",MAX(0,20-MIN(20,D11*5)))) -> ░░░░░░░░░░░░░░░░░░░░
A12: Release management | B12: 2 | C12: =IF(LEN(JD_INPUT!$B$12)<5,0,MIN(2,SUMPRODUCT(--ISNUMBER(SEARCH(TRIM(MID(SUBSTITUTE(KEYWORDS!$B$26,"|",REPT(" ",200)),(ROW(INDIRECT("1:"&KEYWORDS!$C$26))-1)*200+1,200)),JD_INPUT!$B$12))))) -> 0 | D12: =B12*C12 -> 0 | E12: =IF(C12=0,"No keyword match",IF(C12=1,"1 variant matched","2+ variants matched")) -> No keyword match | G12: =IF(C12=0,COUNTIF($C$4:C12,0),"") -> 5 | H12: =IF(D12=0,REPT("░",20),REPT("█",MIN(20,D12*5))&REPT("░",MAX(0,20-MIN(20,D12*5)))) -> ░░░░░░░░░░░░░░░░░░░░
A13: SDLC / Agile / Waterfall | B13: 2 | C13: =IF(LEN(JD_INPUT!$B$12)<5,0,MIN(2,SUMPRODUCT(--ISNUMBER(SEARCH(TRIM(MID(SUBSTITUTE(KEYWORDS!$B$27,"|",REPT(" ",200)),(ROW(INDIRECT("1:"&KEYWORDS!$C$27))-1)*200+1,200)),JD_INPUT!$B$12))))) -> 1 | D13: =B13*C13 -> 2 | E13: =IF(C13=0,"No keyword match",IF(C13=1,"1 variant matched","2+ variants matched")) -> 1 variant matched | G13: =IF(C13=0,COUNTIF($C$4:C13,0),"") | H13: =IF(D13=0,REPT("░",20),REPT("█",MIN(20,D13*5))&REPT("░",MAX(0,20-MIN(20,D13*5)))) -> ██████████░░░░░░░░░░
A14: Enterprise systems | B14: 2 | C14: =IF(LEN(JD_INPUT!$B$12)<5,0,MIN(2,SUMPRODUCT(--ISNUMBER(SEARCH(TRIM(MID(SUBSTITUTE(KEYWORDS!$B$28,"|",REPT(" ",200)),(ROW(INDIRECT("1:"&KEYWORDS!$C$28))-1)*200+1,200)),JD_INPUT!$B$12))))) -> 2 | D14: =B14*C14 -> 4 | E14: =IF(C14=0,"No keyword match",IF(C14=1,"1 variant matched","2+ variants matched")) -> 2+ variants matched | G14: =IF(C14=0,COUNTIF($C$4:C14,0),"") | H14: =IF(D14=0,REPT("░",20),REPT("█",MIN(20,D14*5))&REPT("░",MAX(0,20-MIN(20,D14*5)))) -> ████████████████████
A15: Cloud migration | B15: 2 | C15: =IF(LEN(JD_INPUT!$B$12)<5,0,MIN(2,SUMPRODUCT(--ISNUMBER(SEARCH(TRIM(MID(SUBSTITUTE(KEYWORDS!$B$29,"|",REPT(" ",200)),(ROW(INDIRECT("1:"&KEYWORDS!$C$29))-1)*200+1,200)),JD_INPUT!$B$12))))) -> 0 | D15: =B15*C15 -> 0 | E15: =IF(C15=0,"No keyword match",IF(C15=1,"1 variant matched","2+ variants matched")) -> No keyword match | G15: =IF(C15=0,COUNTIF($C$4:C15,0),"") -> 6 | H15: =IF(D15=0,REPT("░",20),REPT("█",MIN(20,D15*5))&REPT("░",MAX(0,20-MIN(20,D15*5)))) -> ░░░░░░░░░░░░░░░░░░░░
A16: Datacenter migration | B16: 2 | C16: =IF(LEN(JD_INPUT!$B$12)<5,0,MIN(2,SUMPRODUCT(--ISNUMBER(SEARCH(TRIM(MID(SUBSTITUTE(KEYWORDS!$B$30,"|",REPT(" ",200)),(ROW(INDIRECT("1:"&KEYWORDS!$C$30))-1)*200+1,200)),JD_INPUT!$B$12))))) -> 0 | D16: =B16*C16 -> 0 | E16: =IF(C16=0,"No keyword match",IF(C16=1,"1 variant matched","2+ variants matched")) -> No keyword match | G16: =IF(C16=0,COUNTIF($C$4:C16,0),"") -> 7 | H16: =IF(D16=0,REPT("░",20),REPT("█",MIN(20,D16*5))&REPT("░",MAX(0,20-MIN(20,D16*5)))) -> ░░░░░░░░░░░░░░░░░░░░
A17: High availability / reliability | B17: 2 | C17: =IF(LEN(JD_INPUT!$B$12)<5,0,MIN(2,SUMPRODUCT(--ISNUMBER(SEARCH(TRIM(MID(SUBSTITUTE(KEYWORDS!$B$31,"|",REPT(" ",200)),(ROW(INDIRECT("1:"&KEYWORDS!$C$31))-1)*200+1,200)),JD_INPUT!$B$12))))) -> 1 | D17: =B17*C17 -> 2 | E17: =IF(C17=0,"No keyword match",IF(C17=1,"1 variant matched","2+ variants matched")) -> 1 variant matched | G17: =IF(C17=0,COUNTIF($C$4:C17,0),"") | H17: =IF(D17=0,REPT("░",20),REPT("█",MIN(20,D17*5))&REPT("░",MAX(0,20-MIN(20,D17*5)))) -> ██████████░░░░░░░░░░
A18: Vendor management | B18: 2 | C18: =IF(LEN(JD_INPUT!$B$12)<5,0,MIN(2,SUMPRODUCT(--ISNUMBER(SEARCH(TRIM(MID(SUBSTITUTE(KEYWORDS!$B$32,"|",REPT(" ",200)),(ROW(INDIRECT("1:"&KEYWORDS!$C$32))-1)*200+1,200)),JD_INPUT!$B$12))))) -> 0 | D18: =B18*C18 -> 0 | E18: =IF(C18=0,"No keyword match",IF(C18=1,"1 variant matched","2+ variants matched")) -> No keyword match | G18: =IF(C18=0,COUNTIF($C$4:C18,0),"") -> 8 | H18: =IF(D18=0,REPT("░",20),REPT("█",MIN(20,D18*5))&REPT("░",MAX(0,20-MIN(20,D18*5)))) -> ░░░░░░░░░░░░░░░░░░░░
A19: TOTAL KEYWORD SCORE | D19: =SUM(D4:D18) -> 16 | H19: =IF(D19=0,"⏳ Waiting for JD",REPT("█",MIN(30,D19))&" ("&D19&"/30)") -> ████████████████ (16/30)
H20: █████ Strong (4) ██░░░ Partial (2) ░░░░░ Missing (0)
A21: Additional Scoring Factors (Rate 0-5)
A22: Responsibility Pattern Match (0-5) | D22: =MIN(5,IF(ISNUMBER(SEARCH("program",JD_INPUT!$B$12)),1,0)+IF(ISNUMBER(SEARCH("roadmap",JD_INPUT!$B$12)),1,0)+IF(ISNUMBER(SEARCH("delivery",JD_INPUT!$B$12)),1,0)+IF(ISNUMBER(SEARCH("stakeholders",JD_INPUT!$B$12)),1,0)+IF(ISNUMBER(SEARCH("release",JD_INPUT!$B$12)),1,0)) -> 3 | E22: How well does the JD align with TPM responsibility pattern (program delivery, governance)?
A23: Company Match (0-5) | D23: =MIN(5,IF(ISNUMBER(SEARCH("product",JD_INPUT!$B$12)),1,0)+IF(ISNUMBER(SEARCH("platform",JD_INPUT!$B$12)),1,0)+IF(ISNUMBER(SEARCH("engineering",JD_INPUT!$B$12)),1,0)+IF(ISNUMBER(SEARCH("enterprise",JD_INPUT!$B$12)),1,0)+IF(ISNUMBER(SEARCH("gcc",JD_INPUT!$B$12)),1,0)) -> 3 | E23: Is the company a product company, GCC, or consulting tech delivery firm?
A24: Red Flag Penalty (0-5) | D24: =MIN(5,IF(ISNUMBER(SEARCH("helpdesk",JD_INPUT!$B$12)),1,0)+IF(ISNUMBER(SEARCH("l1 support",JD_INPUT!$B$12)),1,0)+IF(ISNUMBER(SEARCH("call center",JD_INPUT!$B$12)),1,0)+IF(ISNUMBER(SEARCH("desktop support",JD_INPUT!$B$12)),1,0)+IF(ISNUMBER(SEARCH("field support",JD_INPUT!$B$12)),1,0)) -> 0 | E24: Penalty if JD is mainly operations/support with no program ownership
A26: FINAL SCORE | D26: =D19+D22+D23-D24 -> 22
A28: Key Gaps / Suggested Edits
A30: TOP MISSING KEYWORDS
A31: Rank | B31: Missing Keyword | C31: Weight | D31: Boost | E31: Action
A32: 1 | B32: =IFERROR(INDEX($A$4:$A$18,MATCH(1,$G$4:$G$18,0)),"All matched") -> Technical program management | C32: =IFERROR(VLOOKUP(B32,$A$4:$B$18,2,FALSE),"-") -> 2 | D32: =IF(ISNUMBER(C32),"+"&(C32*2)&" pts","-") -> +4 pts | E32: ="Add a bullet mentioning: "&B32 -> Add a bullet mentioning: Technical program management
A33: 2 | B33: =IFERROR(INDEX($A$4:$A$18,MATCH(2,$G$4:$G$18,0)),"All matched") -> Program delivery | C33: =IFERROR(VLOOKUP(B33,$A$4:$B$18,2,FALSE),"-") -> 2 | D33: =IF(ISNUMBER(C33),"+"&(C33*2)&" pts","-") -> +4 pts | E33: ="Add a bullet mentioning: "&B33 -> Add a bullet mentioning: Program delivery
A34: 3 | B34: =IFERROR(INDEX($A$4:$A$18,MATCH(3,$G$4:$G$18,0)),"All matched") -> Risk management | C34: =IFERROR(VLOOKUP(B34,$A$4:$B$18,2,FALSE),"-") -> 2 | D34: =IF(ISNUMBER(C34),"+"&(C34*2)&" pts","-") -> +4 pts | E34: ="Add a bullet mentioning: "&B34 -> Add a bullet mentioning: Risk management
A35: 4 | B35: =IFERROR(INDEX($A$4:$A$18,MATCH(4,$G$4:$G$18,0)),"All matched") -> Change management | C35: =IFERROR(VLOOKUP(B35,$A$4:$B$18,2,FALSE),"-") -> 2 | D35: =IF(ISNUMBER(C35),"+"&(C35*2)&" pts","-") -> +4 pts | E35: ="Add a bullet mentioning: "&B35 -> Add a bullet mentioning: Change management
A36: 5 | B36: =IFERROR(INDEX($A$4:$A$18,MATCH(5,$G$4:$G$18,0)),"All matched") -> Release management | C36: =IFERROR(VLOOKUP(B36,$A$4:$B$18,2,FALSE),"-") -> 2 | D36: =IF(ISNUMBER(C36),"+"&(C36*2)&" pts","-") -> +4 pts | E36: ="Add a bullet mentioning: "&B36 -> Add a bullet mentioning: Release management

Sheet ITDM_SCORE
A1: IT Delivery Manager - Scoring
A3: Keyword / Theme | B3: Weight | C3: Auto Score (0,1,2) | D3: Weighted Score | E3: Notes | H3: Contribution
A4: IT delivery management | B4: 2 | C4: =IF(LEN(JD_INPUT!$B$12)<5,0,MIN(2,SUMPRODUCT(--ISNUMBER(SEARCH(TRIM(MID(SUBSTITUTE(KEYWORDS!$B$33,"|",REPT(" ",200)),(ROW(INDIRECT("1:"&KEYWORDS!$C$33))-1)*200+1,200)),JD_INPUT!$B$12))))) -> 0 | D4: =B4*C4 -> 0 | E4: =IF(C4=0,"No keyword match",IF(C4=1,"1 variant matched","2+ variants matched")) -> No keyword match | G4: =IF(C4=0,COUNTIF($C$4:C4,0),"") -> 1 | H4: =IF(D4=0,REPT("░",20),REPT("█",MIN(20,D4*5))&REPT("░",MAX(0,20-MIN(20,D4*5)))) -> ░░░░░░░░░░░░░░░░░░░░
A5: Service delivery | B5: 2 | C5: =IF(LEN(JD_INPUT!$B$12)<5,0,MIN(2,SUMPRODUCT(--ISNUMBER(SEARCH(TRIM(MID(SUBSTITUTE(KEYWORDS!$B$34,"|",REPT(" ",200)),(ROW(INDIRECT("1:"&KEYWORDS!$C$34))-1)*200+1,200)),JD_INPUT!$B$12))))) -> 0 | D5: =B5*C5 -> 0 | E5: =IF(C5=0,"No keyword match",IF(C5=1,"1 variant matched","2+ variants matched")) -> No keyword match | G5: =IF(C5=0,COUNTIF($C$4:C5,0),"") -> 2 | H5: =IF(D5=0,REPT("░",20),REPT("█",MIN(20,D5*5))&REPT("░",MAX(0,20-MIN(20,D5*5)))) -> ░░░░░░░░░░░░░░░░░░░░
A6: SLA management | B6: 2 | C6: =IF(LEN(JD_INPUT!$B$12)<5,0,MIN(2,SUMPRODUCT(--ISNUMBER(SEARCH(TRIM(MID(SUBSTITUTE(KEYWORDS!$B$35,"|",REPT(" ",200)),(ROW(INDIRECT("1:"&KEYWORDS!$C$35))-1)*200+1,200)),JD_INPUT!$B$12))))) -> 1 | D6: =B6*C6 -> 2 | E6: =IF(C6=0,"No keyword match",IF(C6=1,"1 variant matched","2+ variants matched")) -> 1 variant matched | G6: =IF(C6=0,COUNTIF($C$4:C6,0),"") | H6: =IF(D6=0,REPT("░",20),REPT("█",MIN(20,D6*5))&REPT("░",MAX(0,20-MIN(20,D6*5)))) -> ██████████░░░░░░░░░░
A7: Incident management | B7: 2 | C7: =IF(LEN(JD_INPUT!$B$12)<5,0,MIN(2,SUMPRODUCT(--ISNUMBER(SEARCH(TRIM(MID(SUBSTITUTE(KEYWORDS!$B$36,"|",REPT(" ",200)),(ROW(INDIRECT("1:"&KEYWORDS!$C$36))-1)*200+1,200)),JD_INPUT!$B$12))))) -> 0 | D7: =B7*C7 -> 0 | E7: =IF(C7=0,"No keyword match",IF(C7=1,"1 variant matched","2+ variants matched")) -> No keyword match | G7: =IF(C7=0,COUNTIF($C$4:C7,0),"") -> 3 | H7: =IF(D7=0,REPT("░",20),REPT("█",MIN(20,D7*5))&REPT("░",MAX(0,20-MIN(20,D7*5)))) -> ░░░░░░░░░░░░░░░░░░░░
A8: Problem management | B8: 2 | C8: =IF(LEN(JD_INPUT!$B$12)<5,0,MIN(2,SUMPRODUCT(--ISNUMBER(SEARCH(TRIM(MID(SUBSTITUTE(KEYWORDS!$B$37,"|",REPT(" ",200)),(ROW(INDIRECT("1:"&KEYWORDS!$C$37))-1)*200+1,200)),JD_INPUT!$B$12))))) -> 0 | D8: =B8*C8 -> 0 | E8: =IF(C8=0,"No keyword match",IF(C8=1,"1 variant matched","2+ variants matched")) -> No keyword match | G8: =IF(C8=0,COUNTIF($C$4:C8,0),"") -> 4 | H8: =IF(D8=0,REPT("░",20),REPT("█",MIN(20,D8*5))&REPT("░",MAX(0,20-MIN(20,D8*5)))) -> ░░░░░░░░░░░░░░░░░░░░
A9: Change management | B9: 2 | C9: =IF(LEN(JD_INPUT!$B$12)<5,0,MIN(2,SUMPRODUCT(--ISNUMBER(SEARCH(TRIM(MID(SUBSTITUTE(KEYWORDS!$B$38,"|",REPT(" ",200)),(ROW(INDIRECT("1:"&KEYWORDS!$C$38))-1)*200+1,200)),JD_INPUT!$B$12))))) -> 0 | D9: =B9*C9 -> 0 | E9: =IF(C9=0,"No keyword match",IF(C9=1,"1 variant matched","2+ variants matched")) -> No keyword match | G9: =IF(C9=0,COUNTIF($C$4:C9,0),"") -> 5 | H9: =IF(D9=0,REPT("░",20),REPT("█",MIN(20,D9*5))&REPT("░",MAX(0,20-MIN(20,D9*5)))) -> ░░░░░░░░░░░░░░░░░░░░
A10: Release management | B10: 2 | C10: =IF(LEN(JD_INPUT!$B$12)<5,0,MIN(2,SUMPRODUCT(--ISNUMBER(SEARCH(TRIM(MID(SUBSTITUTE(KEYWORDS!$B$39,"|",REPT(" ",200)),(ROW(INDIRECT("1:"&KEYWORDS!$C$39))-1)*200+1,200)),JD_INPUT!$B$12))))) -> 0 | D10: =B10*C10 -> 0 | E10: =IF(C10=0,"No keyword match",IF(C10=1,"1 variant matched","2+ variants matched")) -> No keyword match | G10: =IF(C10=0,COUNTIF($C$4:C10,0),"") -> 6 | H10: =IF(D10=0,REPT("░",20),REPT("█",MIN(20,D10*5))&REPT("░",MAX(0,20-MIN(20,D10*5)))) -> ░░░░░░░░░░░░░░░░░░░░
A11: ITIL | B11: 2 | C11: =IF(LEN(JD_INPUT!$B$12)<5,0,MIN(2,SUMPRODUCT(--ISNUMBER(SEARCH(TRIM(MID(SUBSTITUTE(KEYWORDS!$B$40,"|",REPT(" ",200)),(ROW(INDIRECT("1:"&KEYWORDS!$C$40))-1)*200+1,200)),JD_INPUT!$B$12))))) -> 0 | D11: =B11*C11 -> 0 | E11: =IF(C11=0,"No keyword match",IF(C11=1,"1 variant matched","2+ variants matched")) -> No keyword match | G11: =IF(C11=0,COUNTIF($C$4:C11,0),"") -> 7 | H11: =IF(D11=0,REPT("░",20),REPT("█",MIN(20,D11*5))&REPT("░",MAX(0,20-MIN(20,D11*5)))) -> ░░░░░░░░░░░░░░░░░░░░
A12: ServiceNow | B12: 2 | C12: =IF(LEN(JD_INPUT!$B$12)<5,0,MIN(2,SUMPRODUCT(--ISNUMBER(SEARCH(TRIM(MID(SUBSTITUTE(KEYWORDS!$B$41,"|",REPT(" ",200)),(ROW(INDIRECT("1:"&KEYWORDS!$C$41))-1)*200+1,200)),JD_INPUT!$B$12))))) -> 0 | D12: =B12*C12 -> 0 | E12: =IF(C12=0,"No keyword match",IF(C12=1,"1 variant matched","2+ variants matched")) -> No keyword match | G12: =IF(C12=0,COUNTIF($C$4:C12,0),"") -> 8 | H12: =IF(D12=0,REPT("░",20),REPT("█",MIN(20,D12*5))&REPT("░",MAX(0,20-MIN(20,D12*5)))) -> ░░░░░░░░░░░░░░░░░░░░
A13: Operations management | B13: 2 | C13: =IF(LEN(JD_INPUT!$B$12)<5,0,MIN(2,SUMPRODUCT(--ISNUMBER(SEARCH(TRIM(MID(SUBSTITUTE(KEYWORDS!$B$42,"|",REPT(" ",200)),(ROW(INDIRECT("1:"&KEYWORDS!$C$42))-1)*200+1,200)),JD_INPUT!$B$12))))) -> 0 | D13: =B13*C13 -> 0 | E13: =IF(C13=0,"No keyword match",IF(C13=1,"1 variant matched","2+ variants matched")) -> No keyword match | G13: =IF(C13=0,COUNTIF($C$4:C13,0),"") -> 9 | H13: =IF(D13=0,REPT("░",20),REPT("█",MIN(20,D13*5))&REPT("░",MAX(0,20-MIN(20,D13*5)))) -> ░░░░░░░░░░░░░░░░░░░░
A14: Production support | B14: 2 | C14: =IF(LEN(JD_INPUT!$B$12)<5,0,MIN(2,SUMPRODUCT(--ISNUMBER(SEARCH(TRIM(MID(SUBSTITUTE(KEYWORDS!$B$43,"|",REPT(" ",200)),(ROW(INDIRECT("1:"&KEYWORDS!$C$43))-1)*200+1,200)),JD_INPUT!$B$12))))) -> 0 | D14: =B14*C14 -> 0 | E14: =IF(C14=0,"No keyword match",IF(C14=1,"1 variant matched","2+ variants matched")) -> No keyword match | G14: =IF(C14=0,COUNTIF($C$4:C14,0),"") -> 10 | H14: =IF(D14=0,REPT("░",20),REPT("█",MIN(20,D14*5))&REPT("░",MAX(0,20-MIN(20,D14*5)))) -> ░░░░░░░░░░░░░░░░░░░░
A15: Platform availability / uptime | B15: 2 | C15: =IF(LEN(JD_INPUT!$B$12)<5,0,MIN(2,SUMPRODUCT(--ISNUMBER(SEARCH(TRIM(MID(SUBSTITUTE(KEYWORDS!$B$44,"|",REPT(" ",200)),(ROW(INDIRECT("1:"&KEYWORDS!$C$44))-1)*200+1,200)),JD_INPUT!$B$12))))) -> 1 | D15: =B15*C15 -> 2 | E15: =IF(C15=0,"No keyword match",IF(C15=1,"1 variant matched","2+ variants matched")) -> 1 variant matched | G15: =IF(C15=0,COUNTIF($C$4:C15,0),"") | H15: =IF(D15=0,REPT("░",20),REPT("█",MIN(20,D15*5))&REPT("░",MAX(0,20-MIN(20,D15*5)))) -> ██████████░░░░░░░░░░
A16: Stakeholder management | B16: 2 | C16: =IF(LEN(JD_INPUT!$B$12)<5,0,MIN(2,SUMPRODUCT(--ISNUMBER(SEARCH(TRIM(MID(SUBSTITUTE(KEYWORDS!$B$45,"|",REPT(" ",200)),(ROW(INDIRECT("1:"&KEYWORDS!$C$45))-1)*200+1,200)),JD_INPUT!$B$12))))) -> 0 | D16: =B16*C16 -> 0 | E16: =IF(C16=0,"No keyword match",IF(C16=1,"1 variant matched","2+ variants matched")) -> No keyword match | G16: =IF(C16=0,COUNTIF($C$4:C16,0),"") -> 11 | H16: =IF(D16=0,REPT("░",20),REPT("█",MIN(20,D16*5))&REPT("░",MAX(0,20-MIN(20,D16*5)))) -> ░░░░░░░░░░░░░░░░░░░░
A17: Service improvement | B17: 2 | C17: =IF(LEN(JD_INPUT!$B$12)<5,0,MIN(2,SUMPRODUCT(--ISNUMBER(SEARCH(TRIM(MID(SUBSTITUTE(KEYWORDS!$B$46,"|",REPT(" ",200)),(ROW(INDIRECT("1:"&KEYWORDS!$C$46))-1)*200+1,200)),JD_INPUT!$B$12))))) -> 1 | D17: =B17*C17 -> 2 | E17: =IF(C17=0,"No keyword match",IF(C17=1,"1 variant matched","2+ variants matched")) -> 1 variant matched | G17: =IF(C17=0,COUNTIF($C$4:C17,0),"") | H17: =IF(D17=0,REPT("░",20),REPT("█",MIN(20,D17*5))&REPT("░",MAX(0,20-MIN(20,D17*5)))) -> ██████████░░░░░░░░░░
A18: CRM support / cloud operations | B18: 2 | C18: =IF(LEN(JD_INPUT!$B$12)<5,0,MIN(2,SUMPRODUCT(--ISNUMBER(SEARCH(TRIM(MID(SUBSTITUTE(KEYWORDS!$B$47,"|",REPT(" ",200)),(ROW(INDIRECT("1:"&KEYWORDS!$C$47))-1)*200+1,200)),JD_INPUT!$B$12))))) -> 0 | D18: =B18*C18 -> 0 | E18: =IF(C18=0,"No keyword match",IF(C18=1,"1 variant matched","2+ variants matched")) -> No keyword match | G18: =IF(C18=0,COUNTIF($C$4:C18,0),"") -> 12 | H18: =IF(D18=0,REPT("░",20),REPT("█",MIN(20,D18*5))&REPT("░",MAX(0,20-MIN(20,D18*5)))) -> ░░░░░░░░░░░░░░░░░░░░
A19: TOTAL KEYWORD SCORE | D19: =SUM(D4:D18) -> 6 | H19: =IF(D19=0,"⏳ Waiting for JD",REPT("█",MIN(30,D19))&" ("&D19&"/30)") -> ██████ (6/30)
H20: █████ Strong (4) ██░░░ Partial (2) ░░░░░ Missing (0)
A21: Additional Scoring Factors (Rate 0-5)
A22: Responsibility Pattern Match (0-5) | D22: =MIN(5,IF(ISNUMBER(SEARCH("sla",JD_INPUT!$B$12)),1,0)+IF(ISNUMBER(SEARCH("itil",JD_INPUT!$B$12)),1,0)+IF(ISNUMBER(SEARCH("incident",JD_INPUT!$B$12)),1,0)+IF(ISNUMBER(SEARCH("change management",JD_INPUT!$B$12)),1,0)+IF(ISNUMBER(SEARCH("service delivery",JD_INPUT!$B$12)),1,0)) -> 1 | E22: How well does the JD align with IT Delivery / service operations pattern?
A23: Company Match (0-5) | D23: =MIN(5,IF(ISNUMBER(SEARCH("managed services",JD_INPUT!$B$12)),1,0)+IF(ISNUMBER(SEARCH("support",JD_INPUT!$B$12)),1,0)+IF(ISNUMBER(SEARCH("operations",JD_INPUT!$B$12)),1,0)+IF(ISNUMBER(SEARCH("msp",JD_INPUT!$B$12)),1,0)+IF(ISNUMBER(SEARCH("outsourcing",JD_INPUT!$B$12)),1,0)) -> 2 | E23: Is the company an IT services, managed services, or ops-heavy enterprise?
A24: Red Flag Penalty (0-5) | D24: =MIN(5,IF(ISNUMBER(SEARCH("ai strategy",JD_INPUT!$B$12)),1,0)+IF(ISNUMBER(SEARCH("innovation",JD_INPUT!$B$12)),1,0)+IF(ISNUMBER(SEARCH("transformation roadmap",JD_INPUT!$B$12)),1,0)+IF(ISNUMBER(SEARCH("genai",JD_INPUT!$B$12)),1,0)+IF(ISNUMBER(SEARCH("ai vision",JD_INPUT!$B$12)),1,0)) -> 0 | E24: Penalty if JD is mainly strategy/innovation/AI vision oriented
A26: FINAL SCORE | D26: =D19+D22+D23-D24 -> 9
A28: Key Gaps / Suggested Edits
A30: TOP MISSING KEYWORDS
A31: Rank | B31: Missing Keyword | C31: Weight | D31: Boost | E31: Action
A32: 1 | B32: =IFERROR(INDEX($A$4:$A$18,MATCH(1,$G$4:$G$18,0)),"All matched") -> IT delivery management | C32: =IFERROR(VLOOKUP(B32,$A$4:$B$18,2,FALSE),"-") -> 2 | D32: =IF(ISNUMBER(C32),"+"&(C32*2)&" pts","-") -> +4 pts | E32: ="Add a bullet mentioning: "&B32 -> Add a bullet mentioning: IT delivery management
